Traceback (most recent call last):
  File "/Users/kamiltagowski/anaconda3/envs/amc/lib/python3.9/site-packages/jupyter_cache/executors/utils.py", line 51, in single_nb_execution
    executenb(
  File "/Users/kamiltagowski/anaconda3/envs/amc/lib/python3.9/site-packages/nbclient/client.py", line 1117, in execute
    return NotebookClient(nb=nb, resources=resources, km=km, **kwargs).execute()
  File "/Users/kamiltagowski/anaconda3/envs/amc/lib/python3.9/site-packages/nbclient/util.py", line 78, in wrapped
    return just_run(coro(*args, **kwargs))
  File "/Users/kamiltagowski/anaconda3/envs/amc/lib/python3.9/site-packages/nbclient/util.py", line 57, in just_run
    return loop.run_until_complete(coro)
  File "/Users/kamiltagowski/anaconda3/envs/amc/lib/python3.9/asyncio/base_events.py", line 642, in run_until_complete
    return future.result()
  File "/Users/kamiltagowski/anaconda3/envs/amc/lib/python3.9/site-packages/nbclient/client.py", line 558, in async_execute
    await self.async_execute_cell(
  File "/Users/kamiltagowski/anaconda3/envs/amc/lib/python3.9/site-packages/nbclient/client.py", line 862, in async_execute_cell
    self._check_raise_for_error(cell, exec_reply)
  File "/Users/kamiltagowski/anaconda3/envs/amc/lib/python3.9/site-packages/nbclient/client.py", line 765, in _check_raise_for_error
    raise CellExecutionError.from_cell_and_msg(cell, exec_reply_content)
nbclient.exceptions.CellExecutionError: An error occurred while executing the following cell:
------------------
data = px.data.stocks()

import plotly.graph_objs as go
fig = go.Figure()

fig.add_scatter(
    x=data["date"],
    y=data["AAPL"],
)
fig.update_layout(
    yaxis_title="Close Price Ratio",
    xaxis_title="Date",
    title="AAPL Close Stock Price Ratio 2018-2019"
)
------------------

[0;31m---------------------------------------------------------------------------[0m
[0;31mNameError[0m                                 Traceback (most recent call last)
[0;32m/var/folders/w8/659k99kn2x95s2mmypvk7rjr0000gn/T/ipykernel_82574/3190917362.py[0m in [0;36m<module>[0;34m[0m
[0;32m----> 1[0;31m [0mdata[0m [0;34m=[0m [0mpx[0m[0;34m.[0m[0mdata[0m[0;34m.[0m[0mstocks[0m[0;34m([0m[0;34m)[0m[0;34m[0m[0;34m[0m[0m
[0m[1;32m      2[0m [0;34m[0m[0m
[1;32m      3[0m [0;32mimport[0m [0mplotly[0m[0;34m.[0m[0mgraph_objs[0m [0;32mas[0m [0mgo[0m[0;34m[0m[0;34m[0m[0m
[1;32m      4[0m [0mfig[0m [0;34m=[0m [0mgo[0m[0;34m.[0m[0mFigure[0m[0;34m([0m[0;34m)[0m[0;34m[0m[0;34m[0m[0m
[1;32m      5[0m [0;34m[0m[0m

[0;31mNameError[0m: name 'px' is not defined
NameError: name 'px' is not defined

