Traceback (most recent call last):
  File "/Users/kamiltagowski/anaconda3/envs/amc/lib/python3.9/site-packages/jupyter_cache/executors/utils.py", line 51, in single_nb_execution
    executenb(
  File "/Users/kamiltagowski/anaconda3/envs/amc/lib/python3.9/site-packages/nbclient/client.py", line 1117, in execute
    return NotebookClient(nb=nb, resources=resources, km=km, **kwargs).execute()
  File "/Users/kamiltagowski/anaconda3/envs/amc/lib/python3.9/site-packages/nbclient/util.py", line 78, in wrapped
    return just_run(coro(*args, **kwargs))
  File "/Users/kamiltagowski/anaconda3/envs/amc/lib/python3.9/site-packages/nbclient/util.py", line 57, in just_run
    return loop.run_until_complete(coro)
  File "/Users/kamiltagowski/anaconda3/envs/amc/lib/python3.9/asyncio/base_events.py", line 642, in run_until_complete
    return future.result()
  File "/Users/kamiltagowski/anaconda3/envs/amc/lib/python3.9/site-packages/nbclient/client.py", line 558, in async_execute
    await self.async_execute_cell(
  File "/Users/kamiltagowski/anaconda3/envs/amc/lib/python3.9/site-packages/nbclient/client.py", line 862, in async_execute_cell
    self._check_raise_for_error(cell, exec_reply)
  File "/Users/kamiltagowski/anaconda3/envs/amc/lib/python3.9/site-packages/nbclient/client.py", line 765, in _check_raise_for_error
    raise CellExecutionError.from_cell_and_msg(cell, exec_reply_content)
nbclient.exceptions.CellExecutionError: An error occurred while executing the following cell:
------------------
nx.draw(graph)
------------------

[0;31m---------------------------------------------------------------------------[0m
[0;31mModuleNotFoundError[0m                       Traceback (most recent call last)
[0;32m/var/folders/w8/659k99kn2x95s2mmypvk7rjr0000gn/T/ipykernel_32182/1703950105.py[0m in [0;36m<module>[0;34m[0m
[0;32m----> 1[0;31m [0mnx[0m[0;34m.[0m[0mdraw[0m[0;34m([0m[0mgraph[0m[0;34m)[0m[0;34m[0m[0;34m[0m[0m
[0m
[0;32m~/anaconda3/envs/amc/lib/python3.9/site-packages/networkx/drawing/nx_pylab.py[0m in [0;36mdraw[0;34m(G, pos, ax, **kwds)[0m
[1;32m    103[0m     [0mhttps[0m[0;34m:[0m[0;34m//[0m[0mnetworkx[0m[0;34m.[0m[0morg[0m[0;34m/[0m[0mdocumentation[0m[0;34m/[0m[0mlatest[0m[0;34m/[0m[0mauto_examples[0m[0;34m/[0m[0mindex[0m[0;34m.[0m[0mhtml[0m[0;34m[0m[0;34m[0m[0m
[1;32m    104[0m     """
[0;32m--> 105[0;31m     [0;32mimport[0m [0mmatplotlib[0m[0;34m.[0m[0mpyplot[0m [0;32mas[0m [0mplt[0m[0;34m[0m[0;34m[0m[0m
[0m[1;32m    106[0m [0;34m[0m[0m
[1;32m    107[0m     [0;32mif[0m [0max[0m [0;32mis[0m [0;32mNone[0m[0;34m:[0m[0;34m[0m[0;34m[0m[0m

[0;31mModuleNotFoundError[0m: No module named 'matplotlib'
ModuleNotFoundError: No module named 'matplotlib'

